Workbook
Name Capital_Tot: '11_Performance'!$B$6
Name CatchUpPct: '01_Assumptions'!$B$13
Name DataOggi: '01_Assumptions'!$B$6
Name GPCarry: '01_Assumptions'!$B$11
Name Hurdle: '01_Assumptions'!$B$10
Name Listed_Tot_Cost: '09_Posizioni'!$K$60
Name LPSplit: '01_Assumptions'!$B$12
Name MV_Listed_Tot: '09_Posizioni'!$O$60
Name NAV_Curr: '11_Performance'!$B$16
Name NAVperUnit_Curr: '11_Performance'!$B$18
Name RiskFree: '01_Assumptions'!$B$7
Name Subscription_Pricing_Policy: '01_Assumptions'!$B$8
Name Units_Curr: '11_Performance'!$B$17

Sheet 00_Dashboard
A1: Ariete Capital — Investment Dashboard
A2: Riepilogo aggiornato in tempo reale dai dati dei sheet di input. Tutti i valori sono in EUR.
A4: Data Snapshot | B4: =DataOggi -> 46160
A6: Capitale e NAV | D6: Indicatori di Rendimento
A7: Capitale Raccolto EUR | B7: =Capital_Tot -> 2000000 | D7: IRR (XIRR) | E7: ='11_Performance'!B25 -> -0.020910069
A8: NAV Corrente EUR | B8: =NAV_Curr -> 1971514.5 | D8: CAGR | E8: ='11_Performance'!B26 -> 0
A9: Profitto Totale EUR | B9: =NAV_Curr-Capital_Tot -> -28485.504 | D9: Volatilità Annua | E9: ='11_Performance'!B27 -> 0.06891298
A10: MOIC | B10: =IFERROR(NAV_Curr/Capital_Tot,0) -> 0.98575725 | D10: Sharpe Ratio | E10: ='11_Performance'!B28 -> -0.44360567
A11: Quote Outstanding | B11: =Units_Curr -> 2000000 | D11: Sortino Ratio | E11: ='11_Performance'!B29 -> 0
A12: NAV/Unit | B12: =NAVperUnit_Curr -> 0.98575725 | D12: Max Drawdown | E12: ='11_Performance'!B30 -> -0.050029439
A15: Composizione NAV (EUR) | D15: Flussi Cumulativi (EUR)
A16: Cassa Non Remunerata | B16: ='11_Performance'!B12 -> 611761.75 | C16: =IFERROR(B16/NAV_Curr,0) -> 0.31030041 | D16: Net Trade (Listed) | E16: ='11_Performance'!B7 -> 1082225.7
A17: Strumenti Quotati (MV) | B17: ='11_Performance'!B13 -> 1069752.7 | C17: =IFERROR(B17/NAV_Curr,0) -> 0.54260455 | D17: Dividendi/Interessi Lordi | E17: ='11_Performance'!B8 -> 8226.2
A18: Partecipazioni Non Quotate | B18: ='11_Performance'!B14 -> 155000 | C18: =IFERROR(B18/NAV_Curr,0) -> 0.078619762 | D18: Partecipazioni Net | E18: ='11_Performance'!B9 -> 165000
A19: Prestiti Outstanding | B19: ='11_Performance'!B15 -> 135000 | C19: =IFERROR(B19/NAV_Curr,0) -> 0.068475276 | D19: Prestiti Net | E19: ='11_Performance'!B10 -> 135000
A20: TOTALE NAV | B20: =SUM(B16:B19) -> 1971514.5 | C20: =SUM(C16:C19) -> 1 | D20: P/L Operativa | E20: ='11_Performance'!B11 -> -14238.73
A24: Sommario Waterfall (Ipotetico Oggi)
A25: Hurdle Amount Totale EUR | B25: ='13_Waterfall'!B7 -> 67735.291
A26: Distribuito a LP+GP (capital+pref+split) | B26: ='13_Waterfall'!B22 -> 1971514.5
A27: Carry GP (catch-up + 20%) | B27: ='13_Waterfall'!C22 -> 0

Sheet 01_Assumptions
A1: Ariete Capital — Investment Tracker | Parametri Generali
A2: Tutte le celle gialle in BLU sono input utente. Le celle in NERO sono formule. Le celle in VERDE sono link ad altri sheet.
A4: Parametri Generali
A5: Valuta Base | B5: EUR
A6: Data Odierna (per snapshot) | B6: =TODAY() -> 46160
A7: Tasso Risk-Free Annuo | B7: 0.03 | C7: Modificabile — usato per Sharpe ratio
A8: Subscription Pricing Policy | B8: NAV/Unit del mese precedente la sottoscrizione | C8: Politica di pricing per nuove sottoscrizioni LP
A9: Parametri Waterfall (European-style)
A10: Hurdle Rate (annuo) | B10: 0.05 | C10: Preferred return LP
A11: GP Carry % (post catch-up) | B11: 0.2
A12: LP % (post catch-up) | B12: =1-B11 -> 0.8
A13: Catch-up GP Target % | B13: 0.2 | C13: % del profitto totale che spetta al GP dopo catch-up
A15: Indice del Workbook
A16: 00_Dashboard | B16: Riepilogo KPI principali
A17: 01_Assumptions | B17: Parametri generali, risk-free, waterfall
A18: 02_FX_Rates | B18: Tabella riferimento tassi di cambio
A19: 03_Investitori | B19: Sottoscrizioni di capitale (LP)
A20: 04_Trades | B20: Acquisti/vendite strumenti quotati
A21: 05_Dividendi_Interessi | B21: Dividendi, cedole, interessi (importi LORDI)
A22: 06_Partecipazioni | B22: Acquisti/vendite partecipazioni non quotate
A23: 07_Prestiti | B23: Prestiti verso partecipate (principal)
A24: 08_PL_Operativa | B24: P/L da attività operativa (input manuale)
A25: 09_Posizioni | B25: Posizioni aperte computed
A26: 10_NAV_Mensile | B26: NAV mensile con override valutazioni
A27: 11_Performance | B27: IRR totale, MOIC, Sharpe, drawdown
... A29: 13_Waterfall | B29: Distribuzione waterfall ipotetica oggi

Sheet 02_FX_Rates
A1: Tassi di Cambio — Riferimento
A2: Tabella di riferimento. Ogni transazione contiene la propria colonna FX→EUR per il tasso storico al trade date. Aggiorna questa tabella per facilitare l'inserimento futuro.
A4: Valuta | B4: EUR per 1 unità FX | C4: Ultima Data Aggiornamento | D4: Note
A5: EUR | B5: 1 | D5: Valuta base — sempre 1
A6: USD | B6: 0.92 | D6: Esempio — aggiorna periodicamente
A7: GBP | B7: 1.17
A8: CHF | B8: 1.06
A9: JPY | B9: 0.0061
A10: CNY | B10: 0.13

Sheet 03_Investitori
A1: Sottoscrizioni Capitale (LP)
A2: Ogni riga = una sottoscrizione di capitale da un socio. Per le quote (units), il default NAV/Unit a sottoscrizione è 1.0; per sottoscrizioni successive a movimenti di portafoglio, l'utente può sovrascrivere usando NAV/Unit corrente.
A4: ID | B4: Nome Investitore | C4: Data Sottoscrizione | D4: Tipo | E4: Valuta | F4: Importo Locale | G4: FX→EUR | H4: Importo EUR | I4: NAV/Unit @ Sub | J4: Quote (Units) | K4: % Capitale
A5: =IF(B5="","",ROW()-4) -> 1 | B5: Osy Harrison | C5: 45736 | D5: LP | E5: EUR | F5: 500000 | G5: 1 | H5: =IF(F5="","",F5*G5) -> 500000 | I5: 1 | J5: =IF(OR(H5="",I5="",I5=0),"",H5/I5) -> 500000 | K5: =IF(H5="","",H5/SUM($H$5:$H$104)) -> 0.25
A6: =IF(B6="","",ROW()-4) -> 2 | B6: Bradley Jackson | C6: 45904 | D6: LP | E6: EUR | F6: 500000 | G6: 1 | H6: =IF(F6="","",F6*G6) -> 500000 | I6: 1 | J6: =IF(OR(H6="",I6="",I6=0),"",H6/I6) -> 500000 | K6: =IF(H6="","",H6/SUM($H$5:$H$104)) -> 0.25
A7: =IF(B7="","",ROW()-4) -> 3 | B7: Grant Kauffman | C7: 45910 | D7: LP | E7: EUR | F7: 500000 | G7: 1 | H7: =IF(F7="","",F7*G7) -> 500000 | I7: 1 | J7: =IF(OR(H7="",I7="",I7=0),"",H7/I7) -> 500000 | K7: =IF(H7="","",H7/SUM($H$5:$H$104)) -> 0.25
A8: =IF(B8="","",ROW()-4) -> 4 | B8: Esra Sertoglu | C8: 46097 | D8: LP | E8: EUR | F8: 500000 | G8: 1 | H8: =IF(F8="","",F8*G8) -> 500000 | I8: 1 | J8: =IF(OR(H8="",I8="",I8=0),"",H8/I8) -> 500000 | K8: =IF(H8="","",H8/SUM($H$5:$H$104)) -> 0.25
A9: =IF(B9="","",ROW()-4) | H9: =IF(F9="","",F9*G9) | J9: =IF(OR(H9="",I9="",I9=0),"",H9/I9) | K9: =IF(H9="","",H9/SUM($H$5:$H$104))
A10: =IF(B10="","",ROW()-4) | H10: =IF(F10="","",F10*G10) | J10: =IF(OR(H10="",I10="",I10=0),"",H10/I10) | K10: =IF(H10="","",H10/SUM($H$5:$H$104))
A11: =IF(B11="","",ROW()-4) | H11: =IF(F11="","",F11*G11) | J11: =IF(OR(H11="",I11="",I11=0),"",H11/I11) | K11: =IF(H11="","",H11/SUM($H$5:$H$104))
A12: =IF(B12="","",ROW()-4) | H12: =IF(F12="","",F12*G12) | J12: =IF(OR(H12="",I12="",I12=0),"",H12/I12) | K12: =IF(H12="","",H12/SUM($H$5:$H$104))
A13: =IF(B13="","",ROW()-4) | H13: =IF(F13="","",F13*G13) | J13: =IF(OR(H13="",I13="",I13=0),"",H13/I13) | K13: =IF(H13="","",H13/SUM($H$5:$H$104))
A14: =IF(B14="","",ROW()-4) | H14: =IF(F14="","",F14*G14) | J14: =IF(OR(H14="",I14="",I14=0),"",H14/I14) | K14: =IF(H14="","",H14/SUM($H$5:$H$104))
A15: =IF(B15="","",ROW()-4) | H15: =IF(F15="","",F15*G15) | J15: =IF(OR(H15="",I15="",I15=0),"",H15/I15) | K15: =IF(H15="","",H15/SUM($H$5:$H$104))
A16: =IF(B16="","",ROW()-4) | H16: =IF(F16="","",F16*G16) | J16: =IF(OR(H16="",I16="",I16=0),"",H16/I16) | K16: =IF(H16="","",H16/SUM($H$5:$H$104))
A17: =IF(B17="","",ROW()-4) | H17: =IF(F17="","",F17*G17) | J17: =IF(OR(H17="",I17="",I17=0),"",H17/I17) | K17: =IF(H17="","",H17/SUM($H$5:$H$104))
A18: =IF(B18="","",ROW()-4) | H18: =IF(F18="","",F18*G18) | J18: =IF(OR(H18="",I18="",I18=0),"",H18/I18) | K18: =IF(H18="","",H18/SUM($H$5:$H$104))
A19: =IF(B19="","",ROW()-4) | H19: =IF(F19="","",F19*G19) | J19: =IF(OR(H19="",I19="",I19=0),"",H19/I19) | K19: =IF(H19="","",H19/SUM($H$5:$H$104))
A20: =IF(B20="","",ROW()-4) | H20: =IF(F20="","",F20*G20) | J20: =IF(OR(H20="",I20="",I20=0),"",H20/I20) | K20: =IF(H20="","",H20/SUM($H$5:$H$104))
... A104: =IF(B104="","",ROW()-4) | H104: =IF(F104="","",F104*G104) | J104: =IF(OR(H104="",I104="",I104=0),"",H104/I104) | K104: =IF(H104="","",H104/SUM($H$5:$H$104))
A106: TOTALE | F106: =SUM(F5:F104) -> 2000000 | H106: =SUM(H5:H104) -> 2000000 | J106: =SUM(J5:J104) -> 2000000

Sheet 04_Trades
A1: Acquisti / Vendite Strumenti Quotati
A2: Tipo = BUY o SELL. Importo Locale = Quantità × Prezzo. Le commissioni sono incluse nell'importo (modello al lordo delle imposte). Per ogni trade indicare la valuta e l'FX→EUR al trade date.
A4: ID | B4: Data | C4: Tipo | D4: Nome Strumento | E4: ISIN | F4: Valuta | G4: Quantità | H4: Prezzo Loc. | I4: Importo Loc. | J4: FX→EUR | K4: Importo EUR | L4: Note
A5: =IF(B5="","",ROW()-4) -> 1 | B5: 45658 | C5: BUY | D5: CELSIUS HOLDINGS | E5: US15118V2079 | F5: EUR | G5: 369 | H5: 25.4223 | I5: =IF(OR(G5="",H5=""),"",G5*H5) -> 9380.8287 | J5: 1 | K5: =IF(OR(I5="",J5=""),"",I5*J5) -> 9380.8287 | L5: Posizione di apertura al 01/01/2025 (pre-investitori). Registrato come BUY al valore di mercato 01/01/2025 da Situazione Patrimoniale Directa conto B6166 — questo è il costo di carico ai fini del modello. Liquidità di apertura €371,80 trascurata.
A6: =IF(B6="","",ROW()-4) -> 2 | B6: 45807 | C6: BUY | D6: SANLORENZO | E6: IT0003549422 | F6: EUR | G6: 1000 | H6: 30.55 | I6: =IF(OR(G6="",H6=""),"",G6*H6) -> 30550 | J6: 1 | K6: =IF(OR(I6="",J6=""),"",I6*J6) -> 30550 | L6: Acquisto 30/05/2025 (valuta 03/06/2025), aggregato di 16 eseguiti stesso prezzo. Commissioni €5,00 escluse dall'importo.
A7: =IF(B7="","",ROW()-4) -> 3 | B7: 45831 | C7: BUY | D7: WisdomTree Europe Defence UCITS ETF | E7: IE0002Y8CX98 | F7: EUR | G7: 33 | H7: 29.72 | I7: =IF(OR(G7="",H7=""),"",G7*H7) -> 980.76 | J7: 1 | K7: =IF(OR(I7="",J7=""),"",I7*J7) -> 980.76 | L7: Acquisto 23/06/2025 (valuta 25/06/2025). ETF EUDF/WDEF, EUR Acc, accumulation.
A8: =IF(B8="","",ROW()-4) -> 4 | B8: 45839 | C8: BUY | D8: WisdomTree Europe Defence UCITS ETF | E8: IE0002Y8CX98 | F8: EUR | G8: 33 | H8: 29.68 | I8: =IF(OR(G8="",H8=""),"",G8*H8) -> 979.44 | J8: 1 | K8: =IF(OR(I8="",J8=""),"",I8*J8) -> 979.44 | L8: Acquisto 01/07 valuta 03/07. ETF EUDF/WDEF EUR Acc.
A9: =IF(B9="","",ROW()-4) -> 5 | B9: 45846 | C9: BUY | D9: WisdomTree Europe Defence UCITS ETF | E9: IE0002Y8CX98 | F9: EUR | G9: 32 | H9: 30.625 | I9: =IF(OR(G9="",H9=""),"",G9*H9) -> 980 | J9: 1 | K9: =IF(OR(I9="",J9=""),"",I9*J9) -> 980 | L9: Acquisto 08/07 valuta 10/07.
A10: =IF(B10="","",ROW()-4) -> 6 | B10: 45853 | C10: BUY | D10: CARRARO FINANCE 5.25% Apr30 | E10: IT0006768151 | F10: EUR | G10: 20000 | H10: 1.0174 | I10: =IF(OR(G10="",H10=""),"",G10*H10) -> 20348 | J10: 1 | K10: =IF(OR(I10="",J10=""),"",I10*J10) -> 20348 | L10: Bond Carraro Fin 5,25% scad. 17/04/2030, callable. Nominale €20.000 @ 101,74% = €20.348. Prezzo espresso come decimale (quotazione %/100) per coerenza con formula. Commissioni €5,00 e rateo cedolare €261,07 contabilizzati separatamente.
A11: =IF(B11="","",ROW()-4) -> 7 | B11: 45853 | C11: BUY | D11: BOT Zero Coupon Dec25 | E11: IT0005627853 | F11: EUR | G11: 50000 | H11: 0.99228 | I11: =IF(OR(G11="",H11=""),"",G11*H11) -> 49614 | J11: 1 | K11: =IF(OR(I11="",J11=""),"",I11*J11) -> 49614 | L11: BOT scad. 12/12/2025. Nominale €50.000 @ 99,228% = €49.614. Prezzo in decimale per coerenza formula.
A12: =IF(B12="","",ROW()-4) -> 8 | B12: 45853 | C12: BUY | D12: iShares EUR High Yield Corp Bond UCITS ETF | E12: IE00B66F4759 | F12: EUR | G12: 250 | H12: 94.07 | I12: =IF(OR(G12="",H12=""),"",G12*H12) -> 23517.5 | J12: 1 | K12: =IF(OR(I12="",J12=""),"",I12*J12) -> 23517.5 | L12: ETF IHYG (Dist).
A13: =IF(B13="","",ROW()-4) -> 9 | B13: 45853 | C13: BUY | D13: WisdomTree Europe Defence UCITS ETF | E13: IE0002Y8CX98 | F13: EUR | G13: 32 | H13: 30.55 | I13: =IF(OR(G13="",H13=""),"",G13*H13) -> 977.6 | J13: 1 | K13: =IF(OR(I13="",J13=""),"",I13*J13) -> 977.6
A14: =IF(B14="","",ROW()-4) -> 10 | B14: 45853 | C14: BUY | D14: iShares FTSE MIB UCITS ETF Acc | E14: IE00B53L4X51 | F14: EUR | G14: 13 | H14: 190.28 | I14: =IF(OR(G14="",H14=""),"",G14*H14) -> 2473.64 | J14: 1 | K14: =IF(OR(I14="",J14=""),"",I14*J14) -> 2473.64 | L14: ETF SXRY (Acc).
A15: =IF(B15="","",ROW()-4) -> 11 | B15: 45854 | C15: BUY | D15: EXOR NV | E15: NL0012059018 | F15: EUR | G15: 100 | H15: 88.3 | I15: =IF(OR(G15="",H15=""),"",G15*H15) -> 8830 | J15: 1 | K15: =IF(OR(I15="",J15=""),"",I15*J15) -> 8830 | L15: Commissioni €9,50.
A16: =IF(B16="","",ROW()-4) -> 12 | B16: 45856 | C16: BUY | D16: FERRARI NV | E16: NL0011585146 | F16: EUR | G16: 100 | H16: 435.426 | I16: =IF(OR(G16="",H16=""),"",G16*H16) -> 43542.6 | J16: 1 | K16: =IF(OR(I16="",J16=""),"",I16*J16) -> 43542.6 | L16: Aggregato 6 eseguiti (prezzi 435,40-435,50). Prezzo medio ponderato. Importo totale €43.542,60. Commissioni €5,00.
A17: =IF(B17="","",ROW()-4) -> 13 | B17: 45859 | C17: BUY | D17: Bitwise Physical Bitcoin ETP | E17: DE000A27Z304 | F17: EUR | G17: 1 | H17: 91.865 | I17: =IF(OR(G17="",H17=""),"",G17*H17) -> 91.865 | J17: 1 | K17: =IF(OR(I17="",J17=""),"",I17*J17) -> 91.865 | L17: ETP BTCE.
A18: =IF(B18="","",ROW()-4) -> 14 | B18: 45859 | C18: BUY | D18: ITALGAS | E18: IT0005211237 | F18: EUR | G18: 1000 | H18: 7.215 | I18: =IF(OR(G18="",H18=""),"",G18*H18) -> 7215 | J18: 1 | K18: =IF(OR(I18="",J18=""),"",I18*J18) -> 7215
A19: =IF(B19="","",ROW()-4) -> 15 | B19: 45859 | C19: BUY | D19: ASML HOLDING NV | E19: NL0010273215 | F19: EUR | G19: 20 | H19: 624.3 | I19: =IF(OR(G19="",H19=""),"",G19*H19) -> 12486 | J19: 1 | K19: =IF(OR(I19="",J19=""),"",I19*J19) -> 12486
A20: =IF(B20="","",ROW()-4) -> 16 | B20: 45859 | C20: BUY | D20: PIAGGIO | E20: IT0003073266 | F20: EUR | G20: 5000 | H20: 1.9348 | I20: =IF(OR(G20="",H20=""),"",G20*H20) -> 9674 | J20: 1 | K20: =IF(OR(I20="",J20=""),"",I20*J20) -> 9674 | L20: Aggregato 2 eseguiti (1,934 / 1,935). Importo totale €9.674.
A21: =IF(B21="","",ROW()-4) -> 17 | B21: 45859 | C21: BUY | D21: RAI WAY | E21: IT0005054967 | F21: EUR | G21: 1000 | H21: 5.96621 | I21: =IF(OR(G21="",H21=""),"",G21*H21) -> 5966.21 | J21: 1 | K21: =IF(OR(I21="",J21=""),"",I21*J21) -> 5966.21 | L21: Aggregato 3 eseguiti (5,96-5,97). Importo totale €5.966,21.
A22: =IF(B22="","",ROW()-4) -> 18 | B22: 45859 | C22: BUY | D22: NEXI | E22: IT0005366767 | F22: EUR | G22: 1000 | H22: 5.134 | I22: =IF(OR(G22="",H22=""),"",G22*H22) -> 5134 | J22: 1 | K22: =IF(OR(I22="",J22=""),"",I22*J22) -> 5134
A23: =IF(B23="","",ROW()-4) -> 19 | B23: 45859 | C23: BUY | D23: BOT Zero Coupon Dec25 | E23: IT0005627853 | F23: EUR | G23: 50000 | H23: 0.99255 | I23: =IF(OR(G23="",H23=""),"",G23*H23) -> 49627.5 | J23: 1 | K23: =IF(OR(I23="",J23=""),"",I23*J23) -> 49627.5 | L23: Nominale €50.000 @ 99,255% = €49.627,50. Prezzo in decimale.
A24: =IF(B24="","",ROW()-4) -> 20 | B24: 45859 | C24: BUY | D24: BOT Zero Coupon Jan26 | E24: IT0005631533 | F24: EUR | G24: 20000 | H24: 0.99079 | I24: =IF(OR(G24="",H24=""),"",G24*H24) -> 19815.8 | J24: 1 | K24: =IF(OR(I24="",J24=""),"",I24*J24) -> 19815.8 | L24: BOT scad. 14/01/2026. Nominale €20.000 @ 99,079% = €19.815,80.
A25: =IF(B25="","",ROW()-4) -> 21 | B25: 45860 | C25: BUY | D25: Bitwise Physical Bitcoin ETP | E25: DE000A27Z304 | F25: EUR | G25: 1 | H25: 91.295 | I25: =IF(OR(G25="",H25=""),"",G25*H25) -> 91.295 | J25: 1 | K25: =IF(OR(I25="",J25=""),"",I25*J25) -> 91.295
A26: =IF(B26="","",ROW()-4) -> 22 | B26: 45861 | C26: BUY | D26: Bitwise Physical Bitcoin ETP | E26: DE000A27Z304 | F26: EUR | G26: 1 | H26: 91.065 | I26: =IF(OR(G26="",H26=""),"",G26*H26) -> 91.065 | J26: 1 | K26: =IF(OR(I26="",J26=""),"",I26*J26) -> 91.065
A27: =IF(B27="","",ROW()-4) -> 23 | B27: 45861 | C27: BUY | D27: Bitwise Ethereum Staking ETP | E27: DE000A3G90G9 | F27: EUR | G27: 100 | H27: 6.381 | I27: =IF(OR(G27="",H27=""),"",G27*H27) -> 638.1 | J27: 1 | K27: =IF(OR(I27="",J27=""),"",I27*J27) -> 638.1 | L27: ETP ET32.
A28: =IF(B28="","",ROW()-4) -> 24 | B28: 45861 | C28: BUY | D28: Bitwise Physical Ethereum ETP | E28: DE000A3GMKD7 | F28: EUR | G28: 4 | H28: 29.154 | I28: =IF(OR(G28="",H28=""),"",G28*H28) -> 116.616 | J28: 1 | K28: =IF(OR(I28="",J28=""),"",I28*J28) -> 116.616 | L28: ETP ZETH.
A29: =IF(B29="","",ROW()-4) -> 25 | B29: 45861 | C29: BUY | D29: iShares FTSE MIB UCITS ETF Acc | E29: IE00B53L4X51 | F29: EUR | G29: 12 | H29: 194.54 | I29: =IF(OR(G29="",H29=""),"",G29*H29) -> 2334.48 | J29: 1 | K29: =IF(OR(I29="",J29=""),"",I29*J29) -> 2334.48
A30: =IF(B30="","",ROW()-4) -> 26 | B30: 45861 | C30: BUY | D30: WisdomTree Core Physical Gold | E30: JE00BN2CJ301 | F30: EUR | G30: 1 | H30: 289.55 | I30: =IF(OR(G30="",H30=""),"",G30*H30) -> 289.55 | J30: 1 | K30: =IF(OR(I30="",J30=""),"",I30*J30) -> 289.55 | L30: ETC WGLD.
A31: =IF(B31="","",ROW()-4) -> 27 | B31: 45861 | C31: BUY | D31: WisdomTree Physical Silver | E31: JE00B1VS3333 | F31: EUR | G31: 16 | H31: 30.83 | I31: =IF(OR(G31="",H31=""),"",G31*H31) -> 493.28 | J31: 1 | K31: =IF(OR(I31="",J31=""),"",I31*J31) -> 493.28
A32: =IF(B32="","",ROW()-4) -> 28 | B32: 45861 | C32: BUY | D32: WisdomTree Europe Defence UCITS ETF | E32: IE0002Y8CX98 | F32: EUR | G32: 32 | H32: 30.445 | I32: =IF(OR(G32="",H32=""),"",G32*H32) -> 974.24 | J32: 1 | K32: =IF(OR(I32="",J32=""),"",I32*J32) -> 974.24
A33: =IF(B33="","",ROW()-4) -> 29 | B33: 45862 | C33: BUY | D33: Bitwise Ethereum Staking ETP | E33: DE000A3G90G9 | F33: EUR | G33: 10 | H33: 6.3465 | I33: =IF(OR(G33="",H33=""),"",G33*H33) -> 63.465 | J33: 1 | K33: =IF(OR(I33="",J33=""),"",I33*J33) -> 63.465
A34: =IF(B34="","",ROW()-4) -> 30 | B34: 45862 | C34: BUY | D34: Bitwise Physical Bitcoin ETP | E34: DE000A27Z304 | F34: EUR | G34: 1 | H34: 91.105 | I34: =IF(OR(G34="",H34=""),"",G34*H34) -> 91.105 | J34: 1 | K34: =IF(OR(I34="",J34=""),"",I34*J34) -> 91.105
A35: =IF(B35="","",ROW()-4) -> 31 | B35: 45862 | C35: BUY | D35: Bitwise Physical Ethereum ETP | E35: DE000A3GMKD7 | F35: EUR | G35: 10 | H35: 29.044 | I35: =IF(OR(G35="",H35=""),"",G35*H35) -> 290.44 | J35: 1 | K35: =IF(OR(I35="",J35=""),"",I35*J35) -> 290.44
A36: =IF(B36="","",ROW()-4) -> 32 | B36: 45863 | C36: BUY | D36: Bitwise Ethereum Staking ETP | E36: DE000A3G90G9 | F36: EUR | G36: 10 | H36: 6.369 | I36: =IF(OR(G36="",H36=""),"",G36*H36) -> 63.69 | J36: 1 | K36: =IF(OR(I36="",J36=""),"",I36*J36) -> 63.69
A37: =IF(B37="","",ROW()-4) -> 33 | B37: 45863 | C37: BUY | D37: Bitwise Physical Bitcoin ETP | E37: DE000A27Z304 | F37: EUR | G37: 1 | H37: 88.445 | I37: =IF(OR(G37="",H37=""),"",G37*H37) -> 88.445 | J37: 1 | K37: =IF(OR(I37="",J37=""),"",I37*J37) -> 88.445
A38: =IF(B38="","",ROW()-4) -> 34 | B38: 45863 | C38: BUY | D38: Bitwise Physical Ethereum ETP | E38: DE000A3GMKD7 | F38: EUR | G38: 1 | H38: 29.206 | I38: =IF(OR(G38="",H38=""),"",G38*H38) -> 29.206 | J38: 1 | K38: =IF(OR(I38="",J38=""),"",I38*J38) -> 29.206
A39: =IF(B39="","",ROW()-4) -> 35 | B39: 45863 | C39: BUY | D39: WisdomTree Core Physical Gold | E39: JE00BN2CJ301 | F39: EUR | G39: 10 | H39: 283.37 | I39: =IF(OR(G39="",H39=""),"",G39*H39) -> 2833.7 | J39: 1 | K39: =IF(OR(I39="",J39=""),"",I39*J39) -> 2833.7
A40: =IF(B40="","",ROW()-4) -> 36 | B40: 45863 | C40: BUY | D40: WisdomTree Physical Silver | E40: JE00B1VS3333 | F40: EUR | G40: 10 | H40: 30.275 | I40: =IF(OR(G40="",H40=""),"",G40*H40) -> 302.75 | J40: 1 | K40: =IF(OR(I40="",J40=""),"",I40*J40) -> 302.75
A41: =IF(B41="","",ROW()-4) -> 37 | B41: 45868 | C41: BUY | D41: Bitwise Physical Bitcoin ETP | E41: DE000A27Z304 | F41: EUR | G41: 1 | H41: 92.26 | I41: =IF(OR(G41="",H41=""),"",G41*H41) -> 92.26 | J41: 1 | K41: =IF(OR(I41="",J41=""),"",I41*J41) -> 92.26
...

Sheet 05_Dividendi_Interessi
A1: Dividendi, Cedole, Interessi (al LORDO delle imposte)
A2: Include dividendi azionari, cedole obbligazionarie, interessi su prestiti privati. Tutti gli importi sono al LORDO di ritenute e imposte. Le ritenute non vengono tracciate.
A4: ID | B4: Data | C4: Tipo | D4: Strumento/Controparte | E4: ISIN | F4: Valuta | G4: Lordo Loc. | H4: FX→EUR | I4: Lordo EUR
A5: =IF(B5="","",ROW()-4) -> 1 | B5: 45915 | C5: DIVIDEND | D5: iShares Core MSCI World | E5: IE00B4L5Y983 | F5: EUR | G5: 850 | H5: 1 | I5: =IF(OR(G5="",H5=""),"",G5*H5) -> 850
A6: =IF(B6="","",ROW()-4) -> 2 | B6: 45869 | C6: INTEREST | D6: SANLORENZO — Interessi prestito titoli | E6: IT0003549422 | F6: EUR | G6: 7.47 | H6: 1 | I6: =IF(OR(G6="",H6=""),"",G6*H6) -> 7.47
A7: =IF(B7="","",ROW()-4) -> 3 | B7: 45869 | C7: INTEREST | D7: BOT ZC DEC25 — Interessi prestito titoli | E7: IT0005627853 | F7: EUR | G7: 1.08 | H7: 1 | I7: =IF(OR(G7="",H7=""),"",G7*H7) -> 1.08
A8: =IF(B8="","",ROW()-4) -> 4 | B8: 45875 | C8: DIVIDEND | D8: ASML Holding NV | E8: NL0010273215 | F8: EUR | G8: 27.2 | H8: 1 | I8: =IF(OR(G8="",H8=""),"",G8*H8) -> 27.2
A9: =IF(B9="","",ROW()-4) -> 5 | B9: 45900 | C9: INTEREST | D9: SANLORENZO — Interessi prestito titoli | E9: IT0003549422 | F9: EUR | G9: 3.06 | H9: 1 | I9: =IF(OR(G9="",H9=""),"",G9*H9) -> 3.06
A10: =IF(B10="","",ROW()-4) -> 6 | B10: 45900 | C10: INTEREST | D10: BOT ZC DEC25 — Interessi prestito titoli | E10: IT0005627853 | F10: EUR | G10: 4.86 | H10: 1 | I10: =IF(OR(G10="",H10=""),"",G10*H10) -> 4.86
A11: =IF(B11="","",ROW()-4) -> 7 | B11: 45910 | C11: ETF_INCOME | D11: iShares EUR High Yield Corp Bond UCITS ETF (IHYG) | E11: IE00B66F4759 | F11: EUR | G11: 604.33 | H11: 1 | I11: =IF(OR(G11="",H11=""),"",G11*H11) -> 604.33
A12: =IF(B12="","",ROW()-4) -> 8 | B12: 45919 | C12: DIVIDEND | D12: PIAGGIO | E12: IT0003073266 | F12: EUR | G12: 200 | H12: 1 | I12: =IF(OR(G12="",H12=""),"",G12*H12) -> 200
A13: =IF(B13="","",ROW()-4) -> 9 | B13: 45944 | C13: COUPON | D13: Carraro Finance 5,25% Apr30 — cedola semestrale | E13: IT0006768151 | F13: EUR | G13: 525 | H13: 1 | I13: =IF(OR(G13="",H13=""),"",G13*H13) -> 525
A14: =IF(B14="","",ROW()-4) -> 10 | B14: 45954 | C14: DIVIDEND | D14: ORACLE CORP | E14: US68389X1054 | F14: EUR | G14: 20.12 | H14: 1 | I14: =IF(OR(G14="",H14=""),"",G14*H14) -> 20.12
A15: =IF(B15="","",ROW()-4) -> 11 | B15: 45968 | C15: DIVIDEND | D15: ASML Holding NV | E15: NL0010273215 | F15: EUR | G15: 40.8 | H15: 1 | I15: =IF(OR(G15="",H15=""),"",G15*H15) -> 40.8
A16: =IF(B16="","",ROW()-4) -> 12 | B16: 45981 | C16: DIVIDEND | D16: d'Amico International Shipping | E16: LU2592315662 | F16: EUR | G16: 296.38 | H16: 1 | I16: =IF(OR(G16="",H16=""),"",G16*H16) -> 296.38
... A31: =IF(B31="","",ROW()-4) -> 27 | B31: 46142 | C31: DIVIDEND | D31: IGD | E31: IT0005322612 | F31: EUR | G31: 450 | H31: 1 | I31: =IF(OR(G31="",H31=""),"",G31*H31) -> 450
A32: =IF(B32="","",ROW()-4) | I32: =IF(OR(G32="",H32=""),"",G32*H32)
A33: =IF(B33="","",ROW()-4) | I33: =IF(OR(G33="",H33=""),"",G33*H33)
A34: =IF(B34="","",ROW()-4) | I34: =IF(OR(G34="",H34=""),"",G34*H34)
A35: =IF(B35="","",ROW()-4) | I35: =IF(OR(G35="",H35=""),"",G35*H35)
A36: =IF(B36="","",ROW()-4) | I36: =IF(OR(G36="",H36=""),"",G36*H36)
A37: =IF(B37="","",ROW()-4) | I37: =IF(OR(G37="",H37=""),"",G37*H37)
A38: =IF(B38="","",ROW()-4) | I38: =IF(OR(G38="",H38=""),"",G38*H38)
A39: =IF(B39="","",ROW()-4) | I39: =IF(OR(G39="",H39=""),"",G39*H39)
A40: =IF(B40="","",ROW()-4) | I40: =IF(OR(G40="",H40=""),"",G40*H40)
A41: =IF(B41="","",ROW()-4) | I41: =IF(OR(G41="",H41=""),"",G41*H41)
A42: =IF(B42="","",ROW()-4) | I42: =IF(OR(G42="",H42=""),"",G42*H42)
A43: =IF(B43="","",ROW()-4) | I43: =IF(OR(G43="",H43=""),"",G43*H43)
... A504: =IF(B504="","",ROW()-4) | I504: =IF(OR(G504="",H504=""),"",G504*H504)

Sheet 06_Partecipazioni
A1: Partecipazioni Non Quotate
A2: Acquisti/vendite di quote di società non quotate. 'Valore Corrente EUR' è la valutazione mark-to-market della partecipazione oggi (override manuale). Lasciare vuoto per usare il costo storico.
A4: ID | B4: Data | C4: Tipo | D4: Investee | E4: Quota % | F4: Valuta | G4: Importo Loc. | H4: FX→EUR | I4: Importo EUR | J4: Valore Corrente EUR | K4: Note
A5: =IF(B5="","",ROW()-4) -> 1 | B5: 45940 | C5: BUY | D5: Ariete Tech Solutions | E5: 1 | F5: EUR | G5: 110000 | H5: 1 | I5: =IF(OR(G5="",H5=""),"",G5*H5) -> 110000 | J5: 100000
A6: =IF(B6="","",ROW()-4) -> 2 | B6: 45945 | C6: BUY | D6: BS2 Srl | F6: EUR | G6: 25000 | H6: 1 | I6: =IF(OR(G6="",H6=""),"",G6*H6) -> 25000 | J6: 25000
A7: =IF(B7="","",ROW()-4) -> 3 | B7: 46021 | C7: BUY | D7: Bollette Republic | F7: EUR | G7: 30000 | H7: 1 | I7: =IF(OR(G7="",H7=""),"",G7*H7) -> 30000 | J7: 30000
A8: =IF(B8="","",ROW()-4) | I8: =IF(OR(G8="",H8=""),"",G8*H8)
A9: =IF(B9="","",ROW()-4) | I9: =IF(OR(G9="",H9=""),"",G9*H9)
A10: =IF(B10="","",ROW()-4) | I10: =IF(OR(G10="",H10=""),"",G10*H10)
A11: =IF(B11="","",ROW()-4) | I11: =IF(OR(G11="",H11=""),"",G11*H11)
A12: =IF(B12="","",ROW()-4) | I12: =IF(OR(G12="",H12=""),"",G12*H12)
A13: =IF(B13="","",ROW()-4) | I13: =IF(OR(G13="",H13=""),"",G13*H13)
A14: =IF(B14="","",ROW()-4) | I14: =IF(OR(G14="",H14=""),"",G14*H14)
A15: =IF(B15="","",ROW()-4) | I15: =IF(OR(G15="",H15=""),"",G15*H15)
A16: =IF(B16="","",ROW()-4) | I16: =IF(OR(G16="",H16=""),"",G16*H16)
A17: =IF(B17="","",ROW()-4) | I17: =IF(OR(G17="",H17=""),"",G17*H17)
A18: =IF(B18="","",ROW()-4) | I18: =IF(OR(G18="",H18=""),"",G18*H18)
A19: =IF(B19="","",ROW()-4) | I19: =IF(OR(G19="",H19=""),"",G19*H19)
... A204: =IF(B204="","",ROW()-4) | I204: =IF(OR(G204="",H204=""),"",G204*H204)

Sheet 07_Prestiti
A1: Prestiti Privati verso Partecipate
A2: Solo principal (erogazioni e rimborsi). Gli interessi maturati e ricevuti sui prestiti vanno registrati in 05_Dividendi_Interessi con Tipo = LOAN_INT.
A4: ID | B4: Data | C4: Tipo | D4: Controparte | E4: Valuta | F4: Importo Loc. | G4: FX→EUR | H4: Importo EUR | I4: Outstanding EUR Override | J4: Note
A5: =IF(B5="","",ROW()-4) -> 1 | B5: 45961 | C5: DISBURSEMENT | D5: ATS | E5: EUR | F5: 15000 | G5: 1 | H5: =IF(OR(F5="",G5=""),"",F5*G5) -> 15000
A6: =IF(B6="","",ROW()-4) -> 2 | B6: 45992 | C6: DISBURSEMENT | D6: ATS | E6: EUR | F6: 15000 | G6: 1 | H6: =IF(OR(F6="",G6=""),"",F6*G6) -> 15000
A7: =IF(B7="","",ROW()-4) -> 3 | B7: 46007 | C7: DISBURSEMENT | D7: ATS | E7: EUR | F7: 15000 | G7: 1 | H7: =IF(OR(F7="",G7=""),"",F7*G7) -> 15000
A8: =IF(B8="","",ROW()-4) -> 4 | B8: 46018 | C8: DISBURSEMENT | D8: ATS | E8: EUR | F8: 15000 | G8: 1 | H8: =IF(OR(F8="",G8=""),"",F8*G8) -> 15000
A9: =IF(B9="","",ROW()-4) -> 5 | B9: 46049 | C9: DISBURSEMENT | D9: ATS | E9: EUR | F9: 10000 | G9: 1 | H9: =IF(OR(F9="",G9=""),"",F9*G9) -> 10000
A10: =IF(B10="","",ROW()-4) -> 6 | B10: 46066 | C10: DISBURSEMENT | D10: ATS | E10: EUR | F10: 10000 | G10: 1 | H10: =IF(OR(F10="",G10=""),"",F10*G10) -> 10000
A11: =IF(B11="","",ROW()-4) -> 7 | B11: 46084 | C11: DISBURSEMENT | D11: ATS | E11: EUR | F11: 10000 | G11: 1 | H11: =IF(OR(F11="",G11=""),"",F11*G11) -> 10000
A12: =IF(B12="","",ROW()-4) -> 8 | B12: 46104 | C12: DISBURSEMENT | D12: ATS | E12: EUR | F12: 15000 | G12: 1 | H12: =IF(OR(F12="",G12=""),"",F12*G12) -> 15000
A13: =IF(B13="","",ROW()-4) -> 9 | B13: 46120 | C13: DISBURSEMENT | D13: ATS | E13: EUR | F13: 15000 | G13: 1 | H13: =IF(OR(F13="",G13=""),"",F13*G13) -> 15000
A14: =IF(B14="","",ROW()-4) -> 10 | B14: 46136 | C14: DISBURSEMENT | D14: ATS | E14: EUR | F14: 15000 | G14: 1 | H14: =IF(OR(F14="",G14=""),"",F14*G14) -> 15000
A15: =IF(B15="","",ROW()-4) | H15: =IF(OR(F15="",G15=""),"",F15*G15)
A16: =IF(B16="","",ROW()-4) | H16: =IF(OR(F16="",G16=""),"",F16*G16)
A17: =IF(B17="","",ROW()-4) | H17: =IF(OR(F17="",G17=""),"",F17*G17)
A18: =IF(B18="","",ROW()-4) | H18: =IF(OR(F18="",G18=""),"",F18*G18)
A19: =IF(B19="","",ROW()-4) | H19: =IF(OR(F19="",G19=""),"",F19*G19)
A20: =IF(B20="","",ROW()-4) | H20: =IF(OR(F20="",G20=""),"",F20*G20)
A21: =IF(B21="","",ROW()-4) | H21: =IF(OR(F21="",G21=""),"",F21*G21)
A22: =IF(B22="","",ROW()-4) | H22: =IF(OR(F22="",G22=""),"",F22*G22)
A23: =IF(B23="","",ROW()-4) | H23: =IF(OR(F23="",G23=""),"",F23*G23)
A24: =IF(B24="","",ROW()-4) | H24: =IF(OR(F24="",G24=""),"",F24*G24)
A25: =IF(B25="","",ROW()-4) | H25: =IF(OR(F25="",G25=""),"",F25*G25)
A26: =IF(B26="","",ROW()-4) | H26: =IF(OR(F26="",G26=""),"",F26*G26)
... A204: =IF(B204="","",ROW()-4) | H204: =IF(OR(F204="",G204=""),"",F204*G204)

Sheet 08_PL_Operativa
A1: P/L da Attività Operativa
A2: Input manuale. Inserire il P/L netto dell'attività operativa per periodo: positivo se utile, negativo se perdita. Tutti gli importi sono al LORDO delle imposte.
A4: ID | B4: Data | C4: Categoria | D4: Descrizione | E4: Valuta | F4: P/L Loc. | G4: FX→EUR | H4: P/L EUR | I4: Note
A5: =IF(B5="","",ROW()-4) -> 1 | B5: 45667 | C5: Imposte e bolli | D5: Bollo portafoglio titoli (rif. 31/12/2024) — Directa B6166 | E5: EUR | F5: -4.7 | G5: 1 | H5: =IF(OR(F5="",G5=""),"",F5*G5) -> -4.7
A6: =IF(B6="","",ROW()-4) -> 2 | B6: 45847 | C6: Imposte e bolli | D6: Bollo portafoglio titoli (rif. 30/06/2025) — Directa B6166 | E6: EUR | F6: -45 | G6: 1 | H6: =IF(OR(F6="",G6=""),"",F6*G6) -> -45
A7: =IF(B7="","",ROW()-4) -> 3 | B7: 45853 | C7: Ratei passivi obbligazioni | D7: Rateo cedolare Carraro Finance 5.25% Apr30 acquisto | E7: EUR | F7: -261.07 | G7: 1 | H7: =IF(OR(F7="",G7=""),"",F7*G7) -> -261.07
A8: =IF(B8="","",ROW()-4) -> 4 | B8: 45859 | C8: Imposte e bolli | D8: Tobin Tax Italia (trade italiani del 21/07/2025) | E8: EUR | F8: -27.99 | G8: 1 | H8: =IF(OR(F8="",G8=""),"",F8*G8) -> -27.99
A9: =IF(B9="","",ROW()-4) -> 5 | B9: 45897 | C9: Imposte e bolli | D9: Tobin Tax Italia (acquisto Tamburi 28/08/2025) | E9: EUR | F9: -20.63 | G9: 1 | H9: =IF(OR(F9="",G9=""),"",F9*G9) -> -20.63
A10: =IF(B10="","",ROW()-4) -> 6 | B10: 45910 | C10: Imposte e bolli | D10: Ritenuta provento ETF IHYG (26%) | E10: EUR | F10: -156.73 | G10: 1 | H10: =IF(OR(F10="",G10=""),"",F10*G10) -> -156.73
A11: =IF(B11="","",ROW()-4) -> 7 | B11: 45911 | C11: Imposte e bolli | D11: Tobin Tax Italia (trade italiani del 11/09/2025) | E11: EUR | F11: -4.71 | G11: 1 | H11: =IF(OR(F11="",G11=""),"",F11*G11) -> -4.71
A12: =IF(B12="","",ROW()-4) -> 8 | B12: 45912 | C12: Imposte e bolli | D12: Tobin Tax Italia (trade italiani del 12/09/2025) | E12: EUR | F12: -2.33 | G12: 1 | H12: =IF(OR(F12="",G12=""),"",F12*G12) -> -2.33
A13: =IF(B13="","",ROW()-4) -> 9 | B13: 45917 | C13: Imposte e bolli | D13: Tobin Tax Italia (Tamburi/IGD/WTRE 17/09/2025) | E13: EUR | F13: -8.36 | G13: 1 | H13: =IF(OR(F13="",G13=""),"",F13*G13) -> -8.36
A14: =IF(B14="","",ROW()-4) -> 10 | B14: 45929 | C14: Imposte e bolli | D14: Tobin Tax Italia (acquisti 29/09/2025: B&C, CY4, AMICO, AZM, BC, IP) | E14: EUR | F14: -45.66 | G14: 1 | H14: =IF(OR(F14="",G14=""),"",F14*G14) -> -45.66
A15: =IF(B15="","",ROW()-4) -> 11 | B15: 45932 | C15: Ratei passivi obbligazioni | D15: Rateo cedolare BTP 3.2% Jan26 acquisto | E15: EUR | F15: -243.48 | G15: 1 | H15: =IF(OR(F15="",G15=""),"",F15*G15) -> -243.48
A16: =IF(B16="","",ROW()-4) -> 12 | B16: 45940 | C16: Imposte e bolli | D16: Bollo portafoglio titoli (rif. 30/09/2025) — Directa B6166 | E16: EUR | F16: -272.2 | G16: 1 | H16: =IF(OR(F16="",G16=""),"",F16*G16) -> -272.2
... A31: =IF(B31="","",ROW()-4) -> 27 | B31: 46112 | C31: Risultato | D31: Risultato primo trimestre 2026 | E31: EUR | F31: 64959 | G31: 1 | H31: =IF(OR(F31="",G31=""),"",F31*G31) -> 64959
A32: =IF(B32="","",ROW()-4) | H32: =IF(OR(F32="",G32=""),"",F32*G32)
A33: =IF(B33="","",ROW()-4) | H33: =IF(OR(F33="",G33=""),"",F33*G33)
A34: =IF(B34="","",ROW()-4) | H34: =IF(OR(F34="",G34=""),"",F34*G34)
A35: =IF(B35="","",ROW()-4) | H35: =IF(OR(F35="",G35=""),"",F35*G35)
A36: =IF(B36="","",ROW()-4) | H36: =IF(OR(F36="",G36=""),"",F36*G36)
A37: =IF(B37="","",ROW()-4) | H37: =IF(OR(F37="",G37=""),"",F37*G37)
A38: =IF(B38="","",ROW()-4) | H38: =IF(OR(F38="",G38=""),"",F38*G38)
A39: =IF(B39="","",ROW()-4) | H39: =IF(OR(F39="",G39=""),"",F39*G39)
A40: =IF(B40="","",ROW()-4) | H40: =IF(OR(F40="",G40=""),"",F40*G40)
A41: =IF(B41="","",ROW()-4) | H41: =IF(OR(F41="",G41=""),"",F41*G41)
A42: =IF(B42="","",ROW()-4) | H42: =IF(OR(F42="",G42=""),"",F42*G42)
A43: =IF(B43="","",ROW()-4) | H43: =IF(OR(F43="",G43=""),"",F43*G43)
... A503: =IF(B503="","",ROW()-4) | H503: =IF(OR(F503="",G503=""),"",F503*G503)

Sheet 09_Posizioni
A1: Posizioni Aperte (Strumenti Quotati)
A2: Inserire ogni ISIN una sola volta in colonna B. Le formule calcolano qty netta, market value all'ultimo prezzo di trade (metodologia di valutazione concordata), e P&L. Nome/Valuta sono presi dall'ultimo trade per quell'ISIN.
A4: # | B4: ISIN | C4: Nome (auto) | D4: Valuta (auto) | E4: Qty BUY | F4: Qty SELL | G4: Qty Netta | H4: Ultimo Prezzo Loc. | I4: Ultimo FX | J4: MV Loc. | K4: MV EUR | L4: Costo Medio EUR | M4: P&L Non Realiz. EUR | N4: =" Prezzo Spot @"&TEXT(DataOggi-1,"dd/mm/yy") -> Prezzo Spot @17/05/yy | O4: MV Spot EUR | P4: P&L Spot EUR
A5: =IF(B5="","",ROW()-4) -> 1 | B5: US15118V2079 | C5: =IFERROR(LOOKUP(2,1/('04_Trades'!$E$5:$E$1004=B5),'04_Trades'!$D$5:$D$1004),"") -> CELSIUS HOLDINGS | D5: =IFERROR(LOOKUP(2,1/('04_Trades'!$E$5:$E$1004=B5),'04_Trades'!$F$5:$F$1004),"") -> EUR | E5: =IF(B5="",0,SUMIFS('04_Trades'!$G$5:$G$1004,'04_Trades'!$E$5:$E$1004,B5,'04_Trades'!$C$5:$C$1004,"BUY")) -> 369 | F5: =IF(B5="",0,SUMIFS('04_Trades'!$G$5:$G$1004,'04_Trades'!$E$5:$E$1004,B5,'04_Trades'!$C$5:$C$1004,"SELL")) -> 0 | G5: =IF(B5="","",E5-F5) -> 369 | H5: =IFERROR(LOOKUP(2,1/('04_Trades'!$E$5:$E$1004=B5),'04_Trades'!$H$5:$H$1004),"") -> 25.4223 | I5: =IFERROR(VLOOKUP(D5,'02_FX_Rates'!$A$5:$B$10,2,FALSE),IFERROR(LOOKUP(2,1/('04_Trades'!$E$5:$E$1004=B5),'04_Trades'!$J$5:$J$1004),"")) -> 1 | J5: =IF(OR(B5="",G5="",H5=""),"",G5*H5) -> 9380.8287 | K5: =IF(OR(B5="",J5="",I5=""),"",J5*I5) -> 9380.8287 | L5: =IFERROR(SUMIFS('04_Trades'!$K$5:$K$1004,'04_Trades'!$E$5:$E$1004,B5,'04_Trades'!$C$5:$C$1004,"BUY")/SUMIFS('04_Trades'!$G$5:$G$1004,'04_Trades'!$E$5:$E$1004,B5,'04_Trades'!$C$5:$C$1004,"BUY"),"") -> 25.4223 | M5: =IF(OR(B5="",G5=0,K5="",L5=""),"",K5-G5*L5) -> 0 | N5: 25.42 | O5: =IFERROR(IF(N5="","",G5*N5*I5),"") -> 9379.98 | P5: =IFERROR(IF(OR(N5="",G5=0,L5=""),"",O5-G5*L5),"") -> -0.8487
A6: =IF(B6="","",ROW()-4) -> 2 | B6: IT0003549422 | C6: =IFERROR(LOOKUP(2,1/('04_Trades'!$E$5:$E$1004=B6),'04_Trades'!$D$5:$D$1004),"") -> SANLORENZO | D6: =IFERROR(LOOKUP(2,1/('04_Trades'!$E$5:$E$1004=B6),'04_Trades'!$F$5:$F$1004),"") -> EUR | E6: =IF(B6="",0,SUMIFS('04_Trades'!$G$5:$G$1004,'04_Trades'!$E$5:$E$1004,B6,'04_Trades'!$C$5:$C$1004,"BUY")) -> 1100 | F6: =IF(B6="",0,SUMIFS('04_Trades'!$G$5:$G$1004,'04_Trades'!$E$5:$E$1004,B6,'04_Trades'!$C$5:$C$1004,"SELL")) -> 0 | G6: =IF(B6="","",E6-F6) -> 1100 | H6: =IFERROR(LOOKUP(2,1/('04_Trades'!$E$5:$E$1004=B6),'04_Trades'!$H$5:$H$1004),"") -> 34.2 | I6: =IFERROR(VLOOKUP(D6,'02_FX_Rates'!$A$5:$B$10,2,FALSE),IFERROR(LOOKUP(2,1/('04_Trades'!$E$5:$E$1004=B6),'04_Trades'!$J$5:$J$1004),"")) -> 1 | J6: =IF(OR(B6="",G6="",H6=""),"",G6*H6) -> 37620 | K6: =IF(OR(B6="",J6="",I6=""),"",J6*I6) -> 37620 | L6: =IFERROR(SUMIFS('04_Trades'!$K$5:$K$1004,'04_Trades'!$E$5:$E$1004,B6,'04_Trades'!$C$5:$C$1004,"BUY")/SUMIFS('04_Trades'!$G$5:$G$1004,'04_Trades'!$E$5:$E$1004,B6,'04_Trades'!$C$5:$C$1004,"BUY"),"") -> 30.881818 | M6: =IF(OR(B6="",G6=0,K6="",L6=""),"",K6-G6*L6) -> 3650 | N6: 34.55 | O6: =IFERROR(IF(N6="","",G6*N6*I6),"") -> 38005 | P6: =IFERROR(IF(OR(N6="",G6=0,L6=""),"",O6-G6*L6),"") -> 4035
A7: =IF(B7="","",ROW()-4) -> 3 | B7: IE0002Y8CX98 | C7: =IFERROR(LOOKUP(2,1/('04_Trades'!$E$5:$E$1004=B7),'04_Trades'!$D$5:$D$1004),"") -> WisdomTree Europe Defence UCITS ETF | D7: =IFERROR(LOOKUP(2,1/('04_Trades'!$E$5:$E$1004=B7),'04_Trades'!$F$5:$F$1004),"") -> EUR | E7: =IF(B7="",0,SUMIFS('04_Trades'!$G$5:$G$1004,'04_Trades'!$E$5:$E$1004,B7,'04_Trades'!$C$5:$C$1004,"BUY")) -> 1266 | F7: =IF(B7="",0,SUMIFS('04_Trades'!$G$5:$G$1004,'04_Trades'!$E$5:$E$1004,B7,'04_Trades'!$C$5:$C$1004,"SELL")) -> 0 | G7: =IF(B7="","",E7-F7) -> 1266 | H7: =IFERROR(LOOKUP(2,1/('04_Trades'!$E$5:$E$1004=B7),'04_Trades'!$H$5:$H$1004),"") -> 31.7352 | I7: =IFERROR(VLOOKUP(D7,'02_FX_Rates'!$A$5:$B$10,2,FALSE),IFERROR(LOOKUP(2,1/('04_Trades'!$E$5:$E$1004=B7),'04_Trades'!$J$5:$J$1004),"")) -> 1 | J7: =IF(OR(B7="",G7="",H7=""),"",G7*H7) -> 40176.763 | K7: =IF(OR(B7="",J7="",I7=""),"",J7*I7) -> 40176.763 | L7: =IFERROR(SUMIFS('04_Trades'!$K$5:$K$1004,'04_Trades'!$E$5:$E$1004,B7,'04_Trades'!$C$5:$C$1004,"BUY")/SUMIFS('04_Trades'!$G$5:$G$1004,'04_Trades'!$E$5:$E$1004,B7,'04_Trades'!$C$5:$C$1004,"BUY"),"") -> 31.662912 | M7: =IF(OR(B7="",G7=0,K7="",L7=""),"",K7-G7*L7) -> 91.5162 | N7: 30.65 | O7: =IFERROR(IF(N7="","",G7*N7*I7),"") -> 38802.9 | P7: =IFERROR(IF(OR(N7="",G7=0,L7=""),"",O7-G7*L7),"") -> -1282.347
A8: =IF(B8="","",ROW()-4) -> 4 | B8: IT0006768151 | C8: =IFERROR(LOOKUP(2,1/('04_Trades'!$E$5:$E$1004=B8),'04_Trades'!$D$5:$D$1004),"") -> CARRARO FINANCE 5.25% Apr30 | D8: =IFERROR(LOOKUP(2,1/('04_Trades'!$E$5:$E$1004=B8),'04_Trades'!$F$5:$F$1004),"") -> EUR | E8: =IF(B8="",0,SUMIFS('04_Trades'!$G$5:$G$1004,'04_Trades'!$E$5:$E$1004,B8,'04_Trades'!$C$5:$C$1004,"BUY")) -> 20000 | F8: =IF(B8="",0,SUMIFS('04_Trades'!$G$5:$G$1004,'04_Trades'!$E$5:$E$1004,B8,'04_Trades'!$C$5:$C$1004,"SELL")) -> 0 | G8: =IF(B8="","",E8-F8) -> 20000 | H8: =IFERROR(LOOKUP(2,1/('04_Trades'!$E$5:$E$1004=B8),'04_Trades'!$H$5:$H$1004),"") -> 1.0174 | I8: =IFERROR(VLOOKUP(D8,'02_FX_Rates'!$A$5:$B$10,2,FALSE),IFERROR(LOOKUP(2,1/('04_Trades'!$E$5:$E$1004=B8),'04_Trades'!$J$5:$J$1004),"")) -> 1 | J8: =IF(OR(B8="",G8="",H8=""),"",G8*H8) -> 20348 | K8: =IF(OR(B8="",J8="",I8=""),"",J8*I8) -> 20348 | L8: =IFERROR(SUMIFS('04_Trades'!$K$5:$K$1004,'04_Trades'!$E$5:$E$1004,B8,'04_Trades'!$C$5:$C$1004,"BUY")/SUMIFS('04_Trades'!$G$5:$G$1004,'04_Trades'!$E$5:$E$1004,B8,'04_Trades'!$C$5:$C$1004,"BUY"),"") -> 1.0174 | M8: =IF(OR(B8="",G8=0,K8="",L8=""),"",K8-G8*L8) -> 0 | N8: 1.015 | O8: =IFERROR(IF(N8="","",G8*N8*I8),"") -> 20300 | P8: =IFERROR(IF(OR(N8="",G8=0,L8=""),"",O8-G8*L8),"") -> -48
A9: =IF(B9="","",ROW()-4) -> 5 | B9: IT0005627853 | C9: =IFERROR(LOOKUP(2,1/('04_Trades'!$E$5:$E$1004=B9),'04_Trades'!$D$5:$D$1004),"") -> BOT Zero Coupon Dec25 | D9: =IFERROR(LOOKUP(2,1/('04_Trades'!$E$5:$E$1004=B9),'04_Trades'!$F$5:$F$1004),"") -> EUR | E9: =IF(B9="",0,SUMIFS('04_Trades'!$G$5:$G$1004,'04_Trades'!$E$5:$E$1004,B9,'04_Trades'!$C$5:$C$1004,"BUY")) -> 150000 | F9: =IF(B9="",0,SUMIFS('04_Trades'!$G$5:$G$1004,'04_Trades'!$E$5:$E$1004,B9,'04_Trades'!$C$5:$C$1004,"SELL")) -> 150000 | G9: =IF(B9="","",E9-F9) -> 0 | H9: =IFERROR(LOOKUP(2,1/('04_Trades'!$E$5:$E$1004=B9),'04_Trades'!$H$5:$H$1004),"") -> 1 | I9: =IFERROR(VLOOKUP(D9,'02_FX_Rates'!$A$5:$B$10,2,FALSE),IFERROR(LOOKUP(2,1/('04_Trades'!$E$5:$E$1004=B9),'04_Trades'!$J$5:$J$1004),"")) -> 1 | J9: =IF(OR(B9="",G9="",H9=""),"",G9*H9) -> 0 | K9: =IF(OR(B9="",J9="",I9=""),"",J9*I9) -> 0 | L9: =IFERROR(SUMIFS('04_Trades'!$K$5:$K$1004,'04_Trades'!$E$5:$E$1004,B9,'04_Trades'!$C$5:$C$1004,"BUY")/SUMIFS('04_Trades'!$G$5:$G$1004,'04_Trades'!$E$5:$E$1004,B9,'04_Trades'!$C$5:$C$1004,"BUY"),"") -> 0.993854 | M9: =IF(OR(B9="",G9=0,K9="",L9=""),"",K9-G9*L9) | N9: 1 | O9: =IFERROR(IF(N9="","",G9*N9*I9),"") -> 0 | P9: =IFERROR(IF(OR(N9="",G9=0,L9=""),"",O9-G9*L9),"")
A10: =IF(B10="","",ROW()-4) -> 6 | B10: IE00B66F4759 | C10: =IFERROR(LOOKUP(2,1/('04_Trades'!$E$5:$E$1004=B10),'04_Trades'!$D$5:$D$1004),"") -> iShares EUR High Yield Corp Bond UCITS ETF | D10: =IFERROR(LOOKUP(2,1/('04_Trades'!$E$5:$E$1004=B10),'04_Trades'!$F$5:$F$1004),"") -> EUR | E10: =IF(B10="",0,SUMIFS('04_Trades'!$G$5:$G$1004,'04_Trades'!$E$5:$E$1004,B10,'04_Trades'!$C$5:$C$1004,"BUY")) -> 350 | F10: =IF(B10="",0,SUMIFS('04_Trades'!$G$5:$G$1004,'04_Trades'!$E$5:$E$1004,B10,'04_Trades'!$C$5:$C$1004,"SELL")) -> 0 | G10: =IF(B10="","",E10-F10) -> 350 | H10: =IFERROR(LOOKUP(2,1/('04_Trades'!$E$5:$E$1004=B10),'04_Trades'!$H$5:$H$1004),"") -> 92.9 | I10: =IFERROR(VLOOKUP(D10,'02_FX_Rates'!$A$5:$B$10,2,FALSE),IFERROR(LOOKUP(2,1/('04_Trades'!$E$5:$E$1004=B10),'04_Trades'!$J$5:$J$1004),"")) -> 1 | J10: =IF(OR(B10="",G10="",H10=""),"",G10*H10) -> 32515 | K10: =IF(OR(B10="",J10="",I10=""),"",J10*I10) -> 32515 | L10: =IFERROR(SUMIFS('04_Trades'!$K$5:$K$1004,'04_Trades'!$E$5:$E$1004,B10,'04_Trades'!$C$5:$C$1004,"BUY")/SUMIFS('04_Trades'!$G$5:$G$1004,'04_Trades'!$E$5:$E$1004,B10,'04_Trades'!$C$5:$C$1004,"BUY"),"") -> 93.735714 | M10: =IF(OR(B10="",G10=0,K10="",L10=""),"",K10-G10*L10) -> -292.5 | N10: 91.46 | O10: =IFERROR(IF(N10="","",G10*N10*I10),"") -> 32011 | P10: =IFERROR(IF(OR(N10="",G10=0,L10=""),"",O10-G10*L10),"") -> -796.5
A11: =IF(B11="","",ROW()-4) -> 7 | B11: IE00B53L4X51 | C11: =IFERROR(LOOKUP(2,1/('04_Trades'!$E$5:$E$1004=B11),'04_Trades'!$D$5:$D$1004),"") -> iShares FTSE MIB UCITS ETF Acc | D11: =IFERROR(LOOKUP(2,1/('04_Trades'!$E$5:$E$1004=B11),'04_Trades'!$F$5:$F$1004),"") -> EUR | E11: =IF(B11="",0,SUMIFS('04_Trades'!$G$5:$G$1004,'04_Trades'!$E$5:$E$1004,B11,'04_Trades'!$C$5:$C$1004,"BUY")) -> 398 | F11: =IF(B11="",0,SUMIFS('04_Trades'!$G$5:$G$1004,'04_Trades'!$E$5:$E$1004,B11,'04_Trades'!$C$5:$C$1004,"SELL")) -> 0 | G11: =IF(B11="","",E11-F11) -> 398 | H11: =IFERROR(LOOKUP(2,1/('04_Trades'!$E$5:$E$1004=B11),'04_Trades'!$H$5:$H$1004),"") -> 233.9 | I11: =IFERROR(VLOOKUP(D11,'02_FX_Rates'!$A$5:$B$10,2,FALSE),IFERROR(LOOKUP(2,1/('04_Trades'!$E$5:$E$1004=B11),'04_Trades'!$J$5:$J$1004),"")) -> 1 | J11: =IF(OR(B11="",G11="",H11=""),"",G11*H11) -> 93092.2 | K11: =IF(OR(B11="",J11="",I11=""),"",J11*I11) -> 93092.2 | L11: =IFERROR(SUMIFS('04_Trades'!$K$5:$K$1004,'04_Trades'!$E$5:$E$1004,B11,'04_Trades'!$C$5:$C$1004,"BUY")/SUMIFS('04_Trades'!$G$5:$G$1004,'04_Trades'!$E$5:$E$1004,B11,'04_Trades'!$C$5:$C$1004,"BUY"),"") -> 210.34251 | M11: =IF(OR(B11="",G11=0,K11="",L11=""),"",K11-G11*L11) -> 9375.88 | N11: 242.85 | O11: =IFERROR(IF(N11="","",G11*N11*I11),"") -> 96654.3 | P11: =IFERROR(IF(OR(N11="",G11=0,L11=""),"",O11-G11*L11),"") -> 12937.98
A12: =IF(B12="","",ROW()-4) -> 8 | B12: NL0012059018 | C12: =IFERROR(LOOKUP(2,1/('04_Trades'!$E$5:$E$1004=B12),'04_Trades'!$D$5:$D$1004),"") -> EXOR NV | D12: =IFERROR(LOOKUP(2,1/('04_Trades'!$E$5:$E$1004=B12),'04_Trades'!$F$5:$F$1004),"") -> EUR | E12: =IF(B12="",0,SUMIFS('04_Trades'!$G$5:$G$1004,'04_Trades'!$E$5:$E$1004,B12,'04_Trades'!$C$5:$C$1004,"BUY")) -> 520 | F12: =IF(B12="",0,SUMIFS('04_Trades'!$G$5:$G$1004,'04_Trades'!$E$5:$E$1004,B12,'04_Trades'!$C$5:$C$1004,"SELL")) -> 0 | G12: =IF(B12="","",E12-F12) -> 520 | H12: =IFERROR(LOOKUP(2,1/('04_Trades'!$E$5:$E$1004=B12),'04_Trades'!$H$5:$H$1004),"") -> 75.91475 | I12: =IFERROR(VLOOKUP(D12,'02_FX_Rates'!$A$5:$B$10,2,FALSE),IFERROR(LOOKUP(2,1/('04_Trades'!$E$5:$E$1004=B12),'04_Trades'!$J$5:$J$1004),"")) -> 1 | J12: =IF(OR(B12="",G12="",H12=""),"",G12*H12) -> 39475.67 | K12: =IF(OR(B12="",J12="",I12=""),"",J12*I12) -> 39475.67 | L12: =IFERROR(SUMIFS('04_Trades'!$K$5:$K$1004,'04_Trades'!$E$5:$E$1004,B12,'04_Trades'!$C$5:$C$1004,"BUY")/SUMIFS('04_Trades'!$G$5:$G$1004,'04_Trades'!$E$5:$E$1004,B12,'04_Trades'!$C$5:$C$1004,"BUY"),"") -> 81.542212 | M12: =IF(OR(B12="",G12=0,K12="",L12=""),"",K12-G12*L12) -> -2926.28 | N12: 66.45 | O12: =IFERROR(IF(N12="","",G12*N12*I12),"") -> 34554 | P12: =IFERROR(IF(OR(N12="",G12=0,L12=""),"",O12-G12*L12),"") -> -7847.95
A13: =IF(B13="","",ROW()-4) -> 9 | B13: NL0011585146 | C13: =IFERROR(LOOKUP(2,1/('04_Trades'!$E$5:$E$1004=B13),'04_Trades'!$D$5:$D$1004),"") -> FERRARI NV | D13: =IFERROR(LOOKUP(2,1/('04_Trades'!$E$5:$E$1004=B13),'04_Trades'!$F$5:$F$1004),"") -> EUR | E13: =IF(B13="",0,SUMIFS('04_Trades'!$G$5:$G$1004,'04_Trades'!$E$5:$E$1004,B13,'04_Trades'!$C$5:$C$1004,"BUY")) -> 300 | F13: =IF(B13="",0,SUMIFS('04_Trades'!$G$5:$G$1004,'04_Trades'!$E$5:$E$1004,B13,'04_Trades'!$C$5:$C$1004,"SELL")) -> 0 | G13: =IF(B13="","",E13-F13) -> 300 | H13: =IFERROR(LOOKUP(2,1/('04_Trades'!$E$5:$E$1004=B13),'04_Trades'!$H$5:$H$1004),"") -> 360.418 | I13: =IFERROR(VLOOKUP(D13,'02_FX_Rates'!$A$5:$B$10,2,FALSE),IFERROR(LOOKUP(2,1/('04_Trades'!$E$5:$E$1004=B13),'04_Trades'!$J$5:$J$1004),"")) -> 1 | J13: =IF(OR(B13="",G13="",H13=""),"",G13*H13) -> 108125.4 | K13: =IF(OR(B13="",J13="",I13=""),"",J13*I13) -> 108125.4 | L13: =IFERROR(SUMIFS('04_Trades'!$K$5:$K$1004,'04_Trades'!$E$5:$E$1004,B13,'04_Trades'!$C$5:$C$1004,"BUY")/SUMIFS('04_Trades'!$G$5:$G$1004,'04_Trades'!$E$5:$E$1004,B13,'04_Trades'!$C$5:$C$1004,"BUY"),"") -> 389.241 | M13: =IF(OR(B13="",G13=0,K13="",L13=""),"",K13-G13*L13) -> -8646.9 | N13: 279.75 | O13: =IFERROR(IF(N13="","",G13*N13*I13),"") -> 83925 | P13: =IFERROR(IF(OR(N13="",G13=0,L13=""),"",O13-G13*L13),"") -> -32847.3
A14: =IF(B14="","",ROW()-4) -> 10 | B14: DE000A27Z304 | C14: =IFERROR(LOOKUP(2,1/('04_Trades'!$E$5:$E$1004=B14),'04_Trades'!$D$5:$D$1004),"") -> Bitwise Physical Bitcoin ETP | D14: =IFERROR(LOOKUP(2,1/('04_Trades'!$E$5:$E$1004=B14),'04_Trades'!$F$5:$F$1004),"") -> EUR | E14: =IF(B14="",0,SUMIFS('04_Trades'!$G$5:$G$1004,'04_Trades'!$E$5:$E$1004,B14,'04_Trades'!$C$5:$C$1004,"BUY")) -> 534 | F14: =IF(B14="",0,SUMIFS('04_Trades'!$G$5:$G$1004,'04_Trades'!$E$5:$E$1004,B14,'04_Trades'!$C$5:$C$1004,"SELL")) -> 0 | G14: =IF(B14="","",E14-F14) -> 534 | H14: =IFERROR(LOOKUP(2,1/('04_Trades'!$E$5:$E$1004=B14),'04_Trades'!$H$5:$H$1004),"") -> 50.1552 | I14: =IFERROR(VLOOKUP(D14,'02_FX_Rates'!$A$5:$B$10,2,FALSE),IFERROR(LOOKUP(2,1/('04_Trades'!$E$5:$E$1004=B14),'04_Trades'!$J$5:$J$1004),"")) -> 1 | J14: =IF(OR(B14="",G14="",H14=""),"",G14*H14) -> 26782.877 | K14: =IF(OR(B14="",J14="",I14=""),"",J14*I14) -> 26782.877 | L14: =IFERROR(SUMIFS('04_Trades'!$K$5:$K$1004,'04_Trades'!$E$5:$E$1004,B14,'04_Trades'!$C$5:$C$1004,"BUY")/SUMIFS('04_Trades'!$G$5:$G$1004,'04_Trades'!$E$5:$E$1004,B14,'04_Trades'!$C$5:$C$1004,"BUY"),"") -> 62.698134 | M14: =IF(OR(B14="",G14=0,K14="",L14=""),"",K14-G14*L14) -> -6697.9266 | N14: 60.5 | O14: =IFERROR(IF(N14="","",G14*N14*I14),"") -> 32307 | P14: =IFERROR(IF(OR(N14="",G14=0,L14=""),"",O14-G14*L14),"") -> -1173.8034
A15: =IF(B15="","",ROW()-4) -> 11 | B15: IT0005211237 | C15: =IFERROR(LOOKUP(2,1/('04_Trades'!$E$5:$E$1004=B15),'04_Trades'!$D$5:$D$1004),"") -> ITALGAS | D15: =IFERROR(LOOKUP(2,1/('04_Trades'!$E$5:$E$1004=B15),'04_Trades'!$F$5:$F$1004),"") -> EUR | E15: =IF(B15="",0,SUMIFS('04_Trades'!$G$5:$G$1004,'04_Trades'!$E$5:$E$1004,B15,'04_Trades'!$C$5:$C$1004,"BUY")) -> 1000 | F15: =IF(B15="",0,SUMIFS('04_Trades'!$G$5:$G$1004,'04_Trades'!$E$5:$E$1004,B15,'04_Trades'!$C$5:$C$1004,"SELL")) -> 0 | G15: =IF(B15="","",E15-F15) -> 1000 | H15: =IFERROR(LOOKUP(2,1/('04_Trades'!$E$5:$E$1004=B15),'04_Trades'!$H$5:$H$1004),"") -> 7.215 | I15: =IFERROR(VLOOKUP(D15,'02_FX_Rates'!$A$5:$B$10,2,FALSE),IFERROR(LOOKUP(2,1/('04_Trades'!$E$5:$E$1004=B15),'04_Trades'!$J$5:$J$1004),"")) -> 1 | J15: =IF(OR(B15="",G15="",H15=""),"",G15*H15) -> 7215 | K15: =IF(OR(B15="",J15="",I15=""),"",J15*I15) -> 7215 | L15: =IFERROR(SUMIFS('04_Trades'!$K$5:$K$1004,'04_Trades'!$E$5:$E$1004,B15,'04_Trades'!$C$5:$C$1004,"BUY")/SUMIFS('04_Trades'!$G$5:$G$1004,'04_Trades'!$E$5:$E$1004,B15,'04_Trades'!$C$5:$C$1004,"BUY"),"") -> 7.215 | M15: =IF(OR(B15="",G15=0,K15="",L15=""),"",K15-G15*L15) -> 0 | N15: 7.215 | O15: =IFERROR(IF(N15="","",G15*N15*I15),"") -> 7215 | P15: =IFERROR(IF(OR(N15="",G15=0,L15=""),"",O15-G15*L15),"") -> 0
A16: =IF(B16="","",ROW()-4) -> 12 | B16: NL0010273215 | C16: =IFERROR(LOOKUP(2,1/('04_Trades'!$E$5:$E$1004=B16),'04_Trades'!$D$5:$D$1004),"") -> ASML HOLDING NV | D16: =IFERROR(LOOKUP(2,1/('04_Trades'!$E$5:$E$1004=B16),'04_Trades'!$F$5:$F$1004),"") -> EUR | E16: =IF(B16="",0,SUMIFS('04_Trades'!$G$5:$G$1004,'04_Trades'!$E$5:$E$1004,B16,'04_Trades'!$C$5:$C$1004,"BUY")) -> 30 | F16: =IF(B16="",0,SUMIFS('04_Trades'!$G$5:$G$1004,'04_Trades'!$E$5:$E$1004,B16,'04_Trades'!$C$5:$C$1004,"SELL")) -> 30 | G16: =IF(B16="","",E16-F16) -> 0 | H16: =IFERROR(LOOKUP(2,1/('04_Trades'!$E$5:$E$1004=B16),'04_Trades'!$H$5:$H$1004),"") -> 1141.2 | I16: =IFERROR(VLOOKUP(D16,'02_FX_Rates'!$A$5:$B$10,2,FALSE),IFERROR(LOOKUP(2,1/('04_Trades'!$E$5:$E$1004=B16),'04_Trades'!$J$5:$J$1004),"")) -> 1 | J16: =IF(OR(B16="",G16="",H16=""),"",G16*H16) -> 0 | K16: =IF(OR(B16="",J16="",I16=""),"",J16*I16) -> 0 | L16: =IFERROR(SUMIFS('04_Trades'!$K$5:$K$1004,'04_Trades'!$E$5:$E$1004,B16,'04_Trades'!$C$5:$C$1004,"BUY")/SUMIFS('04_Trades'!$G$5:$G$1004,'04_Trades'!$E$5:$E$1004,B16,'04_Trades'!$C$5:$C$1004,"BUY"),"") -> 615.7 | M16: =IF(OR(B16="",G16=0,K16="",L16=""),"",K16-G16*L16) | N16: 600 | O16: =IFERROR(IF(N16="","",G16*N16*I16),"") -> 0 | P16: =IFERROR(IF(OR(N16="",G16=0,L16=""),"",O16-G16*L16),"")
... A59: =IF(B59="","",ROW()-4) -> 55 | B59: NL0009690239 | C59: =IFERROR(LOOKUP(2,1/('04_Trades'!$E$5:$E$1004=B59),'04_Trades'!$D$5:$D$1004),"") -> VanEck Global Real Estate UCITS ETF | D59: =IFERROR(LOOKUP(2,1/('04_Trades'!$E$5:$E$1004=B59),'04_Trades'!$F$5:$F$1004),"") -> EUR | E59: =IF(B59="",0,SUMIFS('04_Trades'!$G$5:$G$1004,'04_Trades'!$E$5:$E$1004,B59,'04_Trades'!$C$5:$C$1004,"BUY")) -> 124 | F59: =IF(B59="",0,SUMIFS('04_Trades'!$G$5:$G$1004,'04_Trades'!$E$5:$E$1004,B59,'04_Trades'!$C$5:$C$1004,"SELL")) -> 0 | G59: =IF(B59="","",E59-F59) -> 124 | H59: =IFERROR(LOOKUP(2,1/('04_Trades'!$E$5:$E$1004=B59),'04_Trades'!$H$5:$H$1004),"") -> 40.22 | I59: =IFERROR(VLOOKUP(D59,'02_FX_Rates'!$A$5:$B$10,2,FALSE),IFERROR(LOOKUP(2,1/('04_Trades'!$E$5:$E$1004=B59),'04_Trades'!$J$5:$J$1004),"")) -> 1 | J59: =IF(OR(B59="",G59="",H59=""),"",G59*H59) -> 4987.28 | K59: =IF(OR(B59="",J59="",I59=""),"",J59*I59) -> 4987.28 | L59: =IFERROR(SUMIFS('04_Trades'!$K$5:$K$1004,'04_Trades'!$E$5:$E$1004,B59,'04_Trades'!$C$5:$C$1004,"BUY")/SUMIFS('04_Trades'!$G$5:$G$1004,'04_Trades'!$E$5:$E$1004,B59,'04_Trades'!$C$5:$C$1004,"BUY"),"") -> 39.275484 | M59: =IF(OR(B59="",G59=0,K59="",L59=""),"",K59-G59*L59) -> 117.12 | N59: 40.22 | O59: =IFERROR(IF(N59="","",G59*N59*I59),"") -> 4987.28 | P59: =IFERROR(IF(OR(N59="",G59=0,L59=""),"",O59-G59*L59),"") -> 117.12
A60: TOTALE | K60: =SUM(K5:K59) -> 1084431.3 | M60: =SUM(M5:M59) -> -15933.563 | N60: TOTALE | O60: =SUM(O5:O59) -> 1069752.7 | P60: =SUM(P5:P59) -> -30612.134

Sheet 10_NAV_Mensile
A1: NAV Mensile
A2: Inserire la data fine mese in colonna B. Le formule calcolano cassa e NAV (modello al LORDO delle imposte). Per la valutazione di portafoglio quotato, partecipazioni e prestiti in date passate, inserire un override EUR (colonne J-L). Se vuoto, viene usato il costo storico.
A4: # | B4: Data Fine Mese | C4: Capitale Cum. | D4: Net Trade Cum. | E4: Div/Int Lordi Cum. | F4: Part. Net Cum. | G4: Loan Net Cum. | H4: P/L Op. Cum. | I4: Cassa | J4: Listed MV (override) | K4: Part. MV (override) | L4: Loan Outst. (override) | M4: NAV | N4: Quote Outst. | O4: NAV/Unit | P4: Ritorno Mensile
A5: =IF(B5="","",ROW()-4) -> 1 | B5: 45688 | C5: =IF(B5="","",SUMIFS('03_Investitori'!$H$5:$H$104,'03_Investitori'!$C$5:$C$104,"<="&B5)) -> 0 | D5: =IF(B5="","",SUMIFS('04_Trades'!$K$5:$K$1004,'04_Trades'!$C$5:$C$1004,"BUY",'04_Trades'!$B$5:$B$1004,"<="&B5)-SUMIFS('04_Trades'!$K$5:$K$1004,'04_Trades'!$C$5:$C$1004,"SELL",'04_Trades'!$B$5:$B$1004,"<="&B5)) -> 9380.8287 | E5: =IF(B5="","",SUMIFS('05_Dividendi_Interessi'!$I$5:$I$504,'05_Dividendi_Interessi'!$B$5:$B$504,"<="&B5)) -> 0 | F5: =IF(B5="","",SUMIFS('06_Partecipazioni'!$I$5:$I$204,'06_Partecipazioni'!$C$5:$C$204,"BUY",'06_Partecipazioni'!$B$5:$B$204,"<="&B5)-SUMIFS('06_Partecipazioni'!$I$5:$I$204,'06_Partecipazioni'!$C$5:$C$204,"SELL",'06_Partecipazioni'!$B$5:$B$204,"<="&B5)) -> 0 | G5: =IF(B5="","",SUMIFS('07_Prestiti'!$H$5:$H$204,'07_Prestiti'!$C$5:$C$204,"DISBURSEMENT",'07_Prestiti'!$B$5:$B$204,"<="&B5)-SUMIFS('07_Prestiti'!$H$5:$H$204,'07_Prestiti'!$C$5:$C$204,"REPAYMENT",'07_Prestiti'!$B$5:$B$204,"<="&B5)) -> 0 | H5: =IF(B5="","",SUMIFS('08_PL_Operativa'!$H$5:$H$503,'08_PL_Operativa'!$B$5:$B$503,"<="&B5)) -> -4.7 | I5: =IF(B5="","",C5-D5+E5-F5-G5+H5) -> -9385.5287 | M5: =IF(B5="","",I5+IF(AND(MONTH(B5)=MONTH(DataOggi),YEAR(B5)=YEAR(DataOggi)),MV_Listed_Tot,IF(J5="",D5,J5))+IF(K5="",F5,K5)+IF(L5="",G5,L5)) -> -4.7 | N5: =IF(B5="","",SUMIFS('03_Investitori'!$J$5:$J$104,'03_Investitori'!$C$5:$C$104,"<="&B5)) -> 0 | O5: =IF(OR(B5="",N5=0,N5=""),"",M5/N5)
A6: =IF(B6="","",ROW()-4) -> 2 | B6: 45716 | C6: =IF(B6="","",SUMIFS('03_Investitori'!$H$5:$H$104,'03_Investitori'!$C$5:$C$104,"<="&B6)) -> 0 | D6: =IF(B6="","",SUMIFS('04_Trades'!$K$5:$K$1004,'04_Trades'!$C$5:$C$1004,"BUY",'04_Trades'!$B$5:$B$1004,"<="&B6)-SUMIFS('04_Trades'!$K$5:$K$1004,'04_Trades'!$C$5:$C$1004,"SELL",'04_Trades'!$B$5:$B$1004,"<="&B6)) -> 9380.8287 | E6: =IF(B6="","",SUMIFS('05_Dividendi_Interessi'!$I$5:$I$504,'05_Dividendi_Interessi'!$B$5:$B$504,"<="&B6)) -> 0 | F6: =IF(B6="","",SUMIFS('06_Partecipazioni'!$I$5:$I$204,'06_Partecipazioni'!$C$5:$C$204,"BUY",'06_Partecipazioni'!$B$5:$B$204,"<="&B6)-SUMIFS('06_Partecipazioni'!$I$5:$I$204,'06_Partecipazioni'!$C$5:$C$204,"SELL",'06_Partecipazioni'!$B$5:$B$204,"<="&B6)) -> 0 | G6: =IF(B6="","",SUMIFS('07_Prestiti'!$H$5:$H$204,'07_Prestiti'!$C$5:$C$204,"DISBURSEMENT",'07_Prestiti'!$B$5:$B$204,"<="&B6)-SUMIFS('07_Prestiti'!$H$5:$H$204,'07_Prestiti'!$C$5:$C$204,"REPAYMENT",'07_Prestiti'!$B$5:$B$204,"<="&B6)) -> 0 | H6: =IF(B6="","",SUMIFS('08_PL_Operativa'!$H$5:$H$503,'08_PL_Operativa'!$B$5:$B$503,"<="&B6)) -> -4.7 | I6: =IF(B6="","",C6-D6+E6-F6-G6+H6) -> -9385.5287 | M6: =IF(B6="","",I6+IF(AND(MONTH(B6)=MONTH(DataOggi),YEAR(B6)=YEAR(DataOggi)),MV_Listed_Tot,IF(J6="",D6,J6))+IF(K6="",F6,K6)+IF(L6="",G6,L6)) -> -4.7 | N6: =IF(B6="","",SUMIFS('03_Investitori'!$J$5:$J$104,'03_Investitori'!$C$5:$C$104,"<="&B6)) -> 0 | O6: =IF(OR(B6="",N6=0,N6=""),"",M6/N6) | P6: =IFERROR(IF(OR(B6="",O5=""),"",O6/O5-1),"")
A7: =IF(B7="","",ROW()-4) -> 3 | B7: 45747 | C7: =IF(B7="","",SUMIFS('03_Investitori'!$H$5:$H$104,'03_Investitori'!$C$5:$C$104,"<="&B7)) -> 500000 | D7: =IF(B7="","",SUMIFS('04_Trades'!$K$5:$K$1004,'04_Trades'!$C$5:$C$1004,"BUY",'04_Trades'!$B$5:$B$1004,"<="&B7)-SUMIFS('04_Trades'!$K$5:$K$1004,'04_Trades'!$C$5:$C$1004,"SELL",'04_Trades'!$B$5:$B$1004,"<="&B7)) -> 9380.8287 | E7: =IF(B7="","",SUMIFS('05_Dividendi_Interessi'!$I$5:$I$504,'05_Dividendi_Interessi'!$B$5:$B$504,"<="&B7)) -> 0 | F7: =IF(B7="","",SUMIFS('06_Partecipazioni'!$I$5:$I$204,'06_Partecipazioni'!$C$5:$C$204,"BUY",'06_Partecipazioni'!$B$5:$B$204,"<="&B7)-SUMIFS('06_Partecipazioni'!$I$5:$I$204,'06_Partecipazioni'!$C$5:$C$204,"SELL",'06_Partecipazioni'!$B$5:$B$204,"<="&B7)) -> 0 | G7: =IF(B7="","",SUMIFS('07_Prestiti'!$H$5:$H$204,'07_Prestiti'!$C$5:$C$204,"DISBURSEMENT",'07_Prestiti'!$B$5:$B$204,"<="&B7)-SUMIFS('07_Prestiti'!$H$5:$H$204,'07_Prestiti'!$C$5:$C$204,"REPAYMENT",'07_Prestiti'!$B$5:$B$204,"<="&B7)) -> 0 | H7: =IF(B7="","",SUMIFS('08_PL_Operativa'!$H$5:$H$503,'08_PL_Operativa'!$B$5:$B$503,"<="&B7)) -> -4.7 | I7: =IF(B7="","",C7-D7+E7-F7-G7+H7) -> 490614.47 | M7: =IF(B7="","",I7+IF(AND(MONTH(B7)=MONTH(DataOggi),YEAR(B7)=YEAR(DataOggi)),MV_Listed_Tot,IF(J7="",D7,J7))+IF(K7="",F7,K7)+IF(L7="",G7,L7)) -> 499995.3 | N7: =IF(B7="","",SUMIFS('03_Investitori'!$J$5:$J$104,'03_Investitori'!$C$5:$C$104,"<="&B7)) -> 500000 | O7: =IF(OR(B7="",N7=0,N7=""),"",M7/N7) -> 0.9999906 | P7: =IFERROR(IF(OR(B7="",O6=""),"",O7/O6-1),"")
A8: =IF(B8="","",ROW()-4) -> 4 | B8: 45777 | C8: =IF(B8="","",SUMIFS('03_Investitori'!$H$5:$H$104,'03_Investitori'!$C$5:$C$104,"<="&B8)) -> 500000 | D8: =IF(B8="","",SUMIFS('04_Trades'!$K$5:$K$1004,'04_Trades'!$C$5:$C$1004,"BUY",'04_Trades'!$B$5:$B$1004,"<="&B8)-SUMIFS('04_Trades'!$K$5:$K$1004,'04_Trades'!$C$5:$C$1004,"SELL",'04_Trades'!$B$5:$B$1004,"<="&B8)) -> 9380.8287 | E8: =IF(B8="","",SUMIFS('05_Dividendi_Interessi'!$I$5:$I$504,'05_Dividendi_Interessi'!$B$5:$B$504,"<="&B8)) -> 0 | F8: =IF(B8="","",SUMIFS('06_Partecipazioni'!$I$5:$I$204,'06_Partecipazioni'!$C$5:$C$204,"BUY",'06_Partecipazioni'!$B$5:$B$204,"<="&B8)-SUMIFS('06_Partecipazioni'!$I$5:$I$204,'06_Partecipazioni'!$C$5:$C$204,"SELL",'06_Partecipazioni'!$B$5:$B$204,"<="&B8)) -> 0 | G8: =IF(B8="","",SUMIFS('07_Prestiti'!$H$5:$H$204,'07_Prestiti'!$C$5:$C$204,"DISBURSEMENT",'07_Prestiti'!$B$5:$B$204,"<="&B8)-SUMIFS('07_Prestiti'!$H$5:$H$204,'07_Prestiti'!$C$5:$C$204,"REPAYMENT",'07_Prestiti'!$B$5:$B$204,"<="&B8)) -> 0 | H8: =IF(B8="","",SUMIFS('08_PL_Operativa'!$H$5:$H$503,'08_PL_Operativa'!$B$5:$B$503,"<="&B8)) -> -4.7 | I8: =IF(B8="","",C8-D8+E8-F8-G8+H8) -> 490614.47 | M8: =IF(B8="","",I8+IF(AND(MONTH(B8)=MONTH(DataOggi),YEAR(B8)=YEAR(DataOggi)),MV_Listed_Tot,IF(J8="",D8,J8))+IF(K8="",F8,K8)+IF(L8="",G8,L8)) -> 499995.3 | N8: =IF(B8="","",SUMIFS('03_Investitori'!$J$5:$J$104,'03_Investitori'!$C$5:$C$104,"<="&B8)) -> 500000 | O8: =IF(OR(B8="",N8=0,N8=""),"",M8/N8) -> 0.9999906 | P8: =IFERROR(IF(OR(B8="",O7=""),"",O8/O7-1),"") -> 0
A9: =IF(B9="","",ROW()-4) -> 5 | B9: 45808 | C9: =IF(B9="","",SUMIFS('03_Investitori'!$H$5:$H$104,'03_Investitori'!$C$5:$C$104,"<="&B9)) -> 500000 | D9: =IF(B9="","",SUMIFS('04_Trades'!$K$5:$K$1004,'04_Trades'!$C$5:$C$1004,"BUY",'04_Trades'!$B$5:$B$1004,"<="&B9)-SUMIFS('04_Trades'!$K$5:$K$1004,'04_Trades'!$C$5:$C$1004,"SELL",'04_Trades'!$B$5:$B$1004,"<="&B9)) -> 39930.829 | E9: =IF(B9="","",SUMIFS('05_Dividendi_Interessi'!$I$5:$I$504,'05_Dividendi_Interessi'!$B$5:$B$504,"<="&B9)) -> 0 | F9: =IF(B9="","",SUMIFS('06_Partecipazioni'!$I$5:$I$204,'06_Partecipazioni'!$C$5:$C$204,"BUY",'06_Partecipazioni'!$B$5:$B$204,"<="&B9)-SUMIFS('06_Partecipazioni'!$I$5:$I$204,'06_Partecipazioni'!$C$5:$C$204,"SELL",'06_Partecipazioni'!$B$5:$B$204,"<="&B9)) -> 0 | G9: =IF(B9="","",SUMIFS('07_Prestiti'!$H$5:$H$204,'07_Prestiti'!$C$5:$C$204,"DISBURSEMENT",'07_Prestiti'!$B$5:$B$204,"<="&B9)-SUMIFS('07_Prestiti'!$H$5:$H$204,'07_Prestiti'!$C$5:$C$204,"REPAYMENT",'07_Prestiti'!$B$5:$B$204,"<="&B9)) -> 0 | H9: =IF(B9="","",SUMIFS('08_PL_Operativa'!$H$5:$H$503,'08_PL_Operativa'!$B$5:$B$503,"<="&B9)) -> -4.7 | I9: =IF(B9="","",C9-D9+E9-F9-G9+H9) -> 460064.47 | M9: =IF(B9="","",I9+IF(AND(MONTH(B9)=MONTH(DataOggi),YEAR(B9)=YEAR(DataOggi)),MV_Listed_Tot,IF(J9="",D9,J9))+IF(K9="",F9,K9)+IF(L9="",G9,L9)) -> 499995.3 | N9: =IF(B9="","",SUMIFS('03_Investitori'!$J$5:$J$104,'03_Investitori'!$C$5:$C$104,"<="&B9)) -> 500000 | O9: =IF(OR(B9="",N9=0,N9=""),"",M9/N9) -> 0.9999906 | P9: =IFERROR(IF(OR(B9="",O8=""),"",O9/O8-1),"") -> 0
A10: =IF(B10="","",ROW()-4) -> 6 | B10: 45838 | C10: =IF(B10="","",SUMIFS('03_Investitori'!$H$5:$H$104,'03_Investitori'!$C$5:$C$104,"<="&B10)) -> 500000 | D10: =IF(B10="","",SUMIFS('04_Trades'!$K$5:$K$1004,'04_Trades'!$C$5:$C$1004,"BUY",'04_Trades'!$B$5:$B$1004,"<="&B10)-SUMIFS('04_Trades'!$K$5:$K$1004,'04_Trades'!$C$5:$C$1004,"SELL",'04_Trades'!$B$5:$B$1004,"<="&B10)) -> 40911.589 | E10: =IF(B10="","",SUMIFS('05_Dividendi_Interessi'!$I$5:$I$504,'05_Dividendi_Interessi'!$B$5:$B$504,"<="&B10)) -> 0 | F10: =IF(B10="","",SUMIFS('06_Partecipazioni'!$I$5:$I$204,'06_Partecipazioni'!$C$5:$C$204,"BUY",'06_Partecipazioni'!$B$5:$B$204,"<="&B10)-SUMIFS('06_Partecipazioni'!$I$5:$I$204,'06_Partecipazioni'!$C$5:$C$204,"SELL",'06_Partecipazioni'!$B$5:$B$204,"<="&B10)) -> 0 | G10: =IF(B10="","",SUMIFS('07_Prestiti'!$H$5:$H$204,'07_Prestiti'!$C$5:$C$204,"DISBURSEMENT",'07_Prestiti'!$B$5:$B$204,"<="&B10)-SUMIFS('07_Prestiti'!$H$5:$H$204,'07_Prestiti'!$C$5:$C$204,"REPAYMENT",'07_Prestiti'!$B$5:$B$204,"<="&B10)) -> 0 | H10: =IF(B10="","",SUMIFS('08_PL_Operativa'!$H$5:$H$503,'08_PL_Operativa'!$B$5:$B$503,"<="&B10)) -> -4.7 | I10: =IF(B10="","",C10-D10+E10-F10-G10+H10) -> 459083.71 | M10: =IF(B10="","",I10+IF(AND(MONTH(B10)=MONTH(DataOggi),YEAR(B10)=YEAR(DataOggi)),MV_Listed_Tot,IF(J10="",D10,J10))+IF(K10="",F10,K10)+IF(L10="",G10,L10)) -> 499995.3 | N10: =IF(B10="","",SUMIFS('03_Investitori'!$J$5:$J$104,'03_Investitori'!$C$5:$C$104,"<="&B10)) -> 500000 | O10: =IF(OR(B10="",N10=0,N10=""),"",M10/N10) -> 0.9999906 | P10: =IFERROR(IF(OR(B10="",O9=""),"",O10/O9-1),"") -> 0
